<?xml version="1.0" ?>
<!-- =================================================================================== -->
<!-- |    This document was autogenerated by xacro from robot.urdf.xacro               | -->
<!-- |    EDITING THIS FILE BY HAND IS NOT RECOMMENDED                                 | -->
<!-- =================================================================================== -->
<robot name="robot">
  <material name="blue">
    <color rgba="0 0 0.8 1"/>
  </material>
  <material name="black">
    <color rgba="0 0 0 1"/>
  </material>
  <material name="white">
    <color rgba="1 1 1 1"/>
  </material>
  <material name="red">
    <color rgba="1 0 0 1"/>
  </material>
  <link name="base_link">
    <visual>
      <geometry>
        <sphere radius="0.2"/>
      </geometry>
      <material name="red"/>
    </visual>
    <collision>
      <geometry>
        <sphere radius="0.2"/>
      </geometry>
      <material name="red"/>
    </collision>
    <inertial>
      <mass value="20"/>
      <inertia ixx="1e-3" ixy="0.0" ixz="0.0" iyy="1e-3" iyz="0.0" izz="1e-3"/>
    </inertial>
  </link>
  <link name="right_leg">
    <visual>
      <geometry>
        <box size="0.6 0.1 0.2"/>
      </geometry>
      <origin rpy="0 0 0" xyz="0 0 0"/>
      <material name="white"/>
    </visual>
    <collision>
      <geometry>
        <box size="0.6 0.1 0.2"/>
      </geometry>
      <origin rpy="0 0 0" xyz="0 0 0"/>
    </collision>
    <inertial>
      <mass value="10"/>
      <inertia ixx="1e-3" ixy="0.0" ixz="0.0" iyy="1e-3" iyz="0.0" izz="1e-3"/>
    </inertial>
  </link>
  <joint name="base_to_right_leg" type="fixed">
    <parent link="base_link"/>
    <child link="right_leg"/>
    <origin xyz="0.19999999999999998 -0.25 -0.1"/>
  </joint>
  <link name="right_wheel">
    <visual>
      <origin rpy="1.5707963267948966 0 0" xyz="0 0 0"/>
      <geometry>
        <cylinder length="0.1" radius="0.1"/>
      </geometry>
      <material name="black"/>
    </visual>
    <collision>
      <origin rpy="1.5707963267948966 0 0" xyz="0 0 0"/>
      <geometry>
        <cylinder length="0.1" radius="0.1"/>
      </geometry>
    </collision>
    <inertial>
      <mass value="1"/>
      <inertia ixx="1e-3" ixy="0.0" ixz="0.0" iyy="1e-3" iyz="0.0" izz="1e-3"/>
    </inertial>
  </link>
  <joint name="right_wheel_joint" type="continuous">
    <axis rpy="0 0 0" xyz="0 1 0"/>
    <parent link="right_leg"/>
    <child link="right_wheel"/>
    <origin rpy="0 0 0" xyz="-0.19999999999999998 0 -0.1"/>
  </joint>
  <link name="left_leg">
    <visual>
      <geometry>
        <box size="0.6 0.1 0.2"/>
      </geometry>
      <origin rpy="0 0 0" xyz="0 0 0"/>
      <material name="white"/>
    </visual>
    <collision>
      <geometry>
        <box size="0.6 0.1 0.2"/>
      </geometry>
      <origin rpy="0 0 0" xyz="0 0 0"/>
    </collision>
    <inertial>
      <mass value="10"/>
      <inertia ixx="1e-3" ixy="0.0" ixz="0.0" iyy="1e-3" iyz="0.0" izz="1e-3"/>
    </inertial>
  </link>
  <joint name="base_to_left_leg" type="fixed">
    <parent link="base_link"/>
    <child link="left_leg"/>
    <origin xyz="0.19999999999999998 0.25 -0.1"/>
  </joint>
  <link name="left_wheel">
    <visual>
      <origin rpy="1.5707963267948966 0 0" xyz="0 0 0"/>
      <geometry>
        <cylinder length="0.1" radius="0.1"/>
      </geometry>
      <material name="black"/>
    </visual>
    <collision>
      <origin rpy="1.5707963267948966 0 0" xyz="0 0 0"/>
      <geometry>
        <cylinder length="0.1" radius="0.1"/>
      </geometry>
    </collision>
    <inertial>
      <mass value="1"/>
      <inertia ixx="1e-3" ixy="0.0" ixz="0.0" iyy="1e-3" iyz="0.0" izz="1e-3"/>
    </inertial>
  </link>
  <joint name="left_wheel_joint" type="continuous">
    <axis rpy="0 0 0" xyz="0 1 0"/>
    <parent link="left_leg"/>
    <child link="left_wheel"/>
    <origin rpy="0 0 0" xyz="-0.19999999999999998 0 -0.1"/>
  </joint>
  <link name="caster_base">
    <visual>
      <geometry>
        <box size="0.4 0.1 0.1"/>
      </geometry>
      <origin rpy="0 0 1.5707963267948966" xyz="0 0 0"/>
      <material name="red"/>
    </visual>
    <collision>
      <geometry>
        <box size="0.4 0.1 0.1"/>
      </geometry>
      <origin rpy="0 0 1.5707963267948966" xyz="0 0 0"/>
      <material name="red"/>
    </collision>
    <inertial>
      <mass value="10"/>
      <inertia ixx="1e-3" ixy="0.0" ixz="0.0" iyy="1e-3" iyz="0.0" izz="1e-3"/>
    </inertial>
  </link>
  <joint name="base_to_caster_base" type="fixed">
    <parent link="base_link"/>
    <child link="caster_base"/>
    <origin rpy="0 0 0" xyz="0.39999999999999997 0 -0.1"/>
  </joint>
  <link name="caster_wheel">
    <visual>
      <geometry>
        <sphere radius="0.1"/>
      </geometry>
      <material name="black"/>
    </visual>
    <collision>
      <geometry>
        <sphere radius="0.1"/>
      </geometry>
      <material name="black"/>
    </collision>
    <inertial>
      <mass value="2"/>
      <inertia ixx="1e-3" ixy="0.0" ixz="0.0" iyy="1e-3" iyz="0.0" izz="1e-3"/>
    </inertial>
  </link>
  <joint name="caster_wheel_to_caster_base" type="fixed">
    <parent link="caster_base"/>
    <child link="caster_wheel"/>
    <origin rpy="0 0 0" xyz="0 0 -0.1"/>
  </joint>
  <link name="antenna">
    <visual>
      <origin rpy="0 0 0" xyz="0 0 0.2"/>
      <geometry>
        <cylinder length="0.4" radius="0.025"/>
      </geometry>
      <material name="blue"/>
    </visual>
    <collision>
      <origin rpy="0 0 0" xyz="0 0 0.2"/>
      <geometry>
        <cylinder length="0.4" radius="0.025"/>
      </geometry>
      <material name="blue"/>
    </collision>
    <inertial>
      <mass value="5"/>
      <inertia ixx="1e-3" ixy="0.0" ixz="0.0" iyy="1e-3" iyz="0.0" izz="1e-3"/>
    </inertial>
  </link>
  <joint name="antenna_to_base" type="prismatic">
    <parent link="base_link"/>
    <child link="antenna"/>
    <origin rpy="0 0 0" xyz="0 0 -0.2"/>
    <limit effort="1000.0" lower="0" upper="0.4" velocity="0.5"/>
    <axis xyz="0 0 1"/>
  </joint>
  <link name="antenna_plate">
    <visual>
      <geometry>
        <cylinder length="0.025" radius="0.1"/>
      </geometry>
      <material name="blue"/>
    </visual>
    <collision>
      <geometry>
        <cylinder length="0.025" radius="0.1"/>
      </geometry>
      <material name="blue"/>
    </collision>
    <inertial>
      <mass value="2"/>
      <inertia ixx="1e-3" ixy="0.0" ixz="0.0" iyy="1e-3" iyz="0.0" izz="1e-3"/>
    </inertial>
  </link>
  <joint name="antenna_plate_joint" type="continuous">
    <parent link="antenna"/>
    <child link="antenna_plate"/>
    <origin rpy="0 0 0" xyz="0 0 0.4"/>
    <axis xyz="0 0 1"/>
  </joint>
  <link name="right_horn">
    <visual>
      <geometry>
        <cylinder length="0.2" radius="0.02"/>
      </geometry>
      <material name="blue"/>
    </visual>
    <collision>
      <geometry>
        <cylinder length="0.2" radius="0.02"/>
      </geometry>
      <material name="blue"/>
    </collision>
    <inertial>
      <mass value="2"/>
      <inertia ixx="1e-3" ixy="0.0" ixz="0.0" iyy="1e-3" iyz="0.0" izz="1e-3"/>
    </inertial>
  </link>
  <joint name="right_horn_to_antenna_plate" type="fixed">
    <parent link="antenna_plate"/>
    <child link="right_horn"/>
    <origin rpy="0 0 0" xyz="0 -0.05 0.1"/>
  </joint>
  <link name="left_horn">
    <visual>
      <geometry>
        <cylinder length="0.2" radius="0.02"/>
      </geometry>
      <material name="blue"/>
    </visual>
    <collision>
      <geometry>
        <cylinder length="0.2" radius="0.02"/>
      </geometry>
      <material name="blue"/>
    </collision>
    <inertial>
      <mass value="2"/>
      <inertia ixx="1e-3" ixy="0.0" ixz="0.0" iyy="1e-3" iyz="0.0" izz="1e-3"/>
    </inertial>
  </link>
  <joint name="left_horn_to_antenna_plate" type="fixed">
    <parent link="antenna_plate"/>
    <child link="left_horn"/>
    <origin rpy="0 0 0" xyz="0 0.05 0.1"/>
  </joint>
</robot>
